Workbook
Name n_1: {"","одинz","дваz","триz","четыреz","пятьz","шестьz","семьz","восемьz","девятьz"}
Name n_2: {"десятьz","одиннадцатьz","двенадцатьz","тринадцатьz","четырнадцатьz","пятнадцатьz","шестнадцатьz","семнадцатьz","восемнадцатьz","девятнадцатьz"}
Name n_3: {"";1;"двадцатьz";"тридцатьz";"сорокz";"пятьдесятz";"шестьдесятz";"семьдесятz";"восемьдесятz";"девяностоz"}
Name n_4: {"","стоz","двестиz","тристаz","четырестаz","пятьсотz","шестьсотz","семьсотz","восемьсотz","девятьсотz"}
Name n_5: {"","однаz","двеz","триz","четыреz","пятьz","шестьz","семьz","восемьz","девятьz"}
Name n0: "000000000000"&MID(1/2,2,1)&"00"
Name n0x: IF(n_3=1,n_2,n_3&n_1)
Name n1x: IF(n_3=1,n_2,n_3&n_5)
Name мил: {0,"овz";1,"z";2,"аz";5,"овz"}
Name тыс: {0,"тысячz";1,"тысячаz";2,"тысячиz";5,"тысячz"}

Sheet 1
B1: В управление по закупкам ПАО "ЭЛ5-Энерго"
D3: Реквизиты юридического лица | J3: Контактная информация Поставщика
A4: Полное наименование | G4: Юридический адрес
A5: Краткое наименование | G5: Почтовый адрес
A6: ФИО руководителя (подписант) | G6: тел./факс
A7: Должность руководителя | G7: e-mail
A8: действует на основании | D8: Устава/ Доверенности №__ от _____ | G8: Контактное лицо на этапе закупочной процедуры
A9: ИНН | G9: Телефон
A10: КПП | G10: e-mail
A11: Р/с | G11: Контактное лицо на этапе исполнения договора
A12: К/с | G12: Телефон
A13: Банк | G13: e-mail
A14: БИК
A16: ПРЕДЛОЖЕНИЕ НА ПОСТАВКУ ПРОДУКЦИИ
A20: УСЛОВИЯ ОПЛАТЫ | H20: =VLOOKUP($D$20,$S:$Z,4,FALSE) -> 0 | K20: =VLOOKUP($D$20,$S:$Z,8,FALSE) -> 0
A21: ВАЛЮТА | D21: Рубли
A22: Условия оплаты по договору поставки:
A23: Покупатель оплачивает стоимость поставленной продукции не позднее 2-го рабочего дня после истечения 3-х календарных месяцев с даты окончания месяца, в котором были предоставлены Поставщиком Покупателю надлежащим образом оформленные и подписанные Сторонами приемо-сдаточные документы (товарная накладная по форме ТОРГ-12 или УПД) на поставленную продукцию, и предоставлен Поставщиком Покупателю соответствующий оригинал счета-фактуры на стоимость поставленной продукции
A26: УСЛОВИЯ ПОСТАВКИ:
A27: · Пункт отправления груза при поставке:
A28: · Условия поставки:
A29: . Срок поставки:
A30: · Гарантийный срок:
A31: · Дата изготовления
A32: · Обязательства по качеству
A33: · Допустимое отклонение в объеме поставленной продукции, %
A34: · Предоставление Плана контроля качества
A35: · Предоставление Плана контроля качества | B35: Форма заключения договора | G35: в электронной форме с использованием программно-аппаратных средств электронной площадки | O35: выбрать способ заключения договора
A37: По позициям, которые Участник не может поставить, в ячейке «наименование» делается отметка – «не предлагаем», с описанием причины невозможности поставки.
A38: № | B38: № SAP | C38: ОКПД2 | D38: Наименование | E38: чертеж, тех. характеристики | F38: Срок поставки, дней | G38: Ед. изм. | H38: Кол-во | I38: срок поставки, календ. дн. | J38: ="Цена за ед. изм., без НДС, с учетом доставки, "&VLOOKUP($D$21,$S$67:$T$69,2,FALSE) -> Цена за ед. изм., без НДС, с учетом доставки, руб. | K38: ="Стоимость, итого, без НДС, с учетом доставки, "&VLOOKUP($D$21,$S$67:$T$69,2,FALSE) -> Стоимость, итого, без НДС, с учетом доставки, руб. | L38: Производитель | M38: Страна происхождения товара | N38: Номер реестровой записи*
A39: 1 | G39: шт.
A40: 2 | G40: шт.
A41: 3 | G41: шт.
A42: 4
A43: 5
A44: 6
A45: ="Итого без НДС, "&VLOOKUP(D21,$S$67:$T$69,2,FALSE) -> Итого без НДС, руб. | K45: =SUM(K39:K44) -> 0
A46: ="Сумма НДС 22 %, "&VLOOKUP(D21,$S$67:$T$69,2,FALSE) -> Сумма НДС 22 %, руб. | K46: =K47-K45 -> 0
A47: ="Итого с НДС, "&VLOOKUP(D21,$S$67:$T$69,2,FALSE) -> Итого с НДС, руб. | K47: =ROUND(K45*1.2,2) -> 0
A48: * В столбце «Номер реестровой записи» участник указывает номер реестровой записи из реестра российской промышленной продукции или евразийского реестра промышленной продукции (или реестра российского программного обеспечения или реестра евразийского программного обеспечения). В случае отсутствия номера реестровой записи из соответствующего реестра, участник указывает «отсутствует».
...

Sheet Экспорт
A1: Номер договора | B1: дата договора | C1: Место подписания | D1: Подписант ЭР | E1: Подписант ЭР кратко | F1: Контрагент кратко | G1: контрагент полное имя | H1: Подписант ФИО | I1: Подписант ФИО кратко | J1: Подписант должность | K1: доверенность/устав | L1: Предмет | M1: исполнение в лице | N1: филиал | O1: Срок поставки | P1: Контактное лицо ЭР | Q1: Время прибытия | R1: Стоимость цифрами | S1: Поставка +- | T1: Оговорка по поставке+- | U1: Стоимость прописью | V1: НДС цифрами | W1: НДС прописью | X1: Условия оплаты | Y1: Условия оплаты РД | Z1: Юр. адрес | AA1: Почт. Адрес | AB1: тел.общий | AC1: e-mail общ. | AD1: ИНН | AE1: КПП | AF1: р/с | AG1: к/с | AH1: банк | AI1: БИК | AJ1: Контактное лицо | AK1: Тел. Конт.лица | AL1: e-mail конт лица. | AM1: Реквизиты ЭР | AN1: Адрес филиала | AO1: Условия поставки | AP1: Гар. Срок | AQ1: Дата изготовления | AR1: срок действия договора | AS1: ПКК | AU1: Источники | BH1: n_1 | BI1: ={"";"одинz";"дваz";"триz";"четыреz";"пятьz";"шестьz";"семьz";"восемьz";"девятьz"}
A2: ='1'!B57 -> 0 | B2: ='1'!D57 -> 0 | C2: =VLOOKUP('1'!$I$1,Экспорт!$AU:$AW,3,FALSE) -> г. Москва | D2: =VLOOKUP('1'!$I$1,Экспорт!$AU:$AV,2,FALSE) -> Директора по закупкам Гринькива Антона Тарасовича, действующего на основании Доверенности № 123/2015 от 10.06.2015 г. | E2: =VLOOKUP('1'!$I$1,Экспорт!$AU:$AX,4,FALSE) -> А.Т. Гринькив | F2: ='1'!$D$5 | G2: ='1'!$D$4 | H2: ='1'!$D$6 | I2: =MID(H2,(FIND(" ",H2)+1),1)&"."&MID(H2,(FIND(" ",H2,FIND(" ",H2)+1))+1,1)&". "&LEFT(H2,FIND(" ",H2)-1) -> . . | J2: ='1'!D7 | K2: ='1'!D8 -> Устава/ Доверенности №__ от _____ | L2: =CONCATENATE('1'!A17," ",'1'!A18) | M2: =VLOOKUP(N2,$AV$11:$AW$16,2,FALSE) -> #N/A | N2: =VLOOKUP('1'!$A$18,Экспорт!$AU$11:$AV$16,2,FALSE) -> #N/A | O2: ='1'!G29 -> 0 | P2: =VLOOKUP(N2,$AV$11:$AX$16,3,FALSE) -> #N/A | Q2: =VLOOKUP(N2,$AV$11:$AY$16,4,FALSE) -> #N/A | R2: ='1'!$K$47 -> 0 | S2: =IF('1'!$G$33=0,"",CONCATENATE("2.10. Налив (загрузка) продукции в цистерны (тару) производится до полной вместимости, исходя из технических норм загрузки. Покупатель обязан принять и оплатить продукцию за фактически поставленное количество",", если перелив или недолив (перегруз или недогруз) связан с соблюдением технических норм загрузки цистерны (тары). Допускается отклонение в объеме поставленной продукции в пределах +/- ",'1'!$G$33,"% от указанного в спецификации, являющейся неотъемлемой частью настоящего Договора.")) | T2: =IF(S2="","","Сумма договора является окончательной до полного исполнения сторонами договорных обязательств, за исключением случаев указанных в п.2.10. настоящего Договора.") | U2: =VLOOKUP('1'!$D$21,Экспорт!$AU$19:$AV$21,2,FALSE) -> Ноль рублей 00 копеек | V2: =ROUND(R2/1.18*0.18,2) -> 0 | W2: =VLOOKUP('1'!$D$21,Экспорт!$AU$23:$AV$25,2,FALSE) -> Ноль рублей 00 копеек | X2: ='1'!$A$23 -> Покупатель оплачивает стоимость поставленной продукции не позднее 2-го рабочего дня после истечения 3-х календарных месяцев с даты окончания месяца, в котором были предоставлены Поставщиком Покупателю надлежащим образом оформленные и подписанные Сторонами приемо-сдаточные документы (товарная накладная по форме ТОРГ-12 или УПД) на поставленную продукцию, и предоставлен Поставщиком Покупателю соответствующий оригинал счета-фактуры на стоимость поставленной продукции | Y2: =SUBSTITUTE(X2,"продукции по Договору","продукции по Заказу к Договору") -> Покупатель оплачивает стоимость поставленной продукции не позднее 2-го рабочего дня после истечения 3-х календарных месяцев с даты окончания месяца, в котором были предоставлены Поставщиком Покупателю надлежащим образом оформленные и подписанные Сторонами приемо-сдаточные документы (товарная накладная по форме ТОРГ-12 или УПД) на поставленную продукцию, и предоставлен Поставщиком Покупателю соответствующий оригинал счета-фактуры на стоимость поставленной продукции | Z2: ='1'!$J$4 | AA2: ='1'!$J$5 | AB2: ='1'!J6 | AC2: ='1'!$J$7 | AD2: ='1'!D9 | AE2: ='1'!D10 | AF2: ='1'!D11 | AG2: ='1'!D12 | AH2: ='1'!D13 | AI2: ='1'!D14 | AJ2: ='1'!J11 | AK2: ='1'!J12 | AL2: ='1'!J13 | AM2: =CONCATENATE($AZ$17," Грузополучатель: ",VLOOKUP('1'!A18,Экспорт!$AU$11:$AZ$16,6,FALSE)) -> #N/A | AN2: =VLOOKUP('1'!A18,Экспорт!$AU$11:$BA$15,7,FALSE) -> #N/A | AO2: ='1'!$G$28&IF('1'!$G$27=0,""," Пункт отправления груза при поставке: "&'1'!$G$27&".") | AP2: ='1'!$G$30 -> 0 | AQ2: ='1'!$G$31 -> 0 | AR2: =EOMONTH(TODAY(),12) -> 46630 | AS2: ='1'!$G$34 -> 0 | AU2: ='1'!S59 -> 0 | AV2: Директора по закупкам Гринькива Антона Тарасовича, действующего на основании Доверенности № 123/2015 от 10.06.2015 г. | AW2: г. Москва | AX2: А.Т. Гринькив | AZ2: 115093, г. Москва, ул. Павловская, дом 7, строение 1 | BH2: n_2 | BI2: ={"десятьz";"одиннадцатьz";"двенадцатьz";"тринадцатьz";"четырнадцатьz";"пятнадцатьz";"шестнадцатьz";"семнадцатьz";"восемнадцатьz";"девятнадцатьz"}
AU3: ='1'!S60 -> 0 | AV3: менеджера группы закупок филиала «Невинномысская ГРЭС» Кулигина Александра Владимировича, действующего на основании доверенности №149/2015 от 03.07.2015 г. | AW3: г. Невинномысск | AX3: А.В. Кулигин | AZ3: 357107, Ставропольский край, г. Невинномысск, ул. Энергетиков, 2 | BH3: n_3 | BI3: ={"":1:"двадцатьz":"тридцатьz":"сорокz":"пятьдесятz":"шестьдесятz":"семьдесятz":"восемьдесятz":"девяностоz"}
AU4: ='1'!S61 -> 0 | AV4: менеджера группы закупок филиала «Среднеуральская ГРЭС» Рассказовой Светланы Валерьевны, действующего на основании доверенности №150/2015 от 03.07.2015 г. | AW4: г. Среднеуральск | AX4: С.В. Рассказова | AZ4: 624070, Свердловская обл., г. Среднеуральск, ул. Ленина, 2 | BH4: n_4 | BI4: ={"";"стоz";"двестиz";"тристаz";"четырестаz";"пятьсотz";"шестьсотz";"семьсотz";"восемьсотz";"девятьсотz"}
AU5: ='1'!S62 -> 0 | AV5: менеджера группы закупок филиала «Рефтинская ГРЭС» Денисенко Ирины Анатольевны, действующего на основании доверенности №17/2016 от 26.01.2016 г. | AW5: п. Рефтинский | AX5: И.А. Денисенко | AZ5: 624285, РФ, Свердловская область, г. Асбест, пос. Рефтинский | BH5: n_5 | BI5: ={"";"однаz";"двеz";"триz";"четыреz";"пятьz";"шестьz";"семьz";"восемьz";"девятьz"}
AU6: ='1'!S63 -> 0 | AV6: менеджера группы закупок филиала «Конаковская ГРЭС» Никифоровой Галины Анатольевны, действующего на основании доверенности №262/2015 от 02.10.2015 г. | AW6: г. Конаково | AX6: Г.А. Никифорова | AZ6: 171252, Тверская обл.,г.Конаково, ул. Промышленная, д.12
AU7: ='1'!S64 -> 0 | AV7: Исполняющего обязанности Директора по закупкам Томильцева Владимира Александровича, действующего на основании Доверенности №319/2015 от 26.11.2015 г. | AW7: г. Москва | AX7: В.А. Томильцев | AZ7: 115093, г. Москва, ул. Павловская, дом 7, строение 1
AU8: ='1'!S65 -> 0 | AV8: Генерального директора Карло Палашано Вилламанья, действующего на основании Устава | AW8: г. Москва | AX8: К. Палашано Вилламанья | AZ8: 115093, г. Москва, ул. Павловская, дом 7, строение 1
AU11: для нужд филиала «Среднеуральская ГРЭС» ПАО «Энел Россия» | AV11: «Среднеуральская ГРЭС» | AW11: в лице своего филиала | AX11: Менеджер ТМЦ Андреев Дмитрий Николаевич Dmitry.Andreev@enel.com +7 34368 2 5367 | AY11: По согласованию с Грузополучателем | AZ11: Филиал «Среднеуральская ГРЭС» ПАО «Энел Россия» 624070, Свердловская обл., г. Среднеуральск, ул. Ленина, 2 ИНН 6671156423 / КПП 660602001 Тел. (34368)25946, Факс: (343) 3595445 | BA11: 624070, Свердловская обл., г. Среднеуральск, ул. Ленина, 2
AU12: для нужд филиала «Рефтинская ГРЭС» ПАО «Энел Россия» | AV12: «Рефтинская ГРЭС» | AW12: в лице своего филиала | AX12: Менеджер ТМЦ Дубровина Наталья Валентиновна Natalia.Dubrovina@enel.com +7 34365 3 6713 | AY12: Понедельник – среда: до 16-00; Пятница до 15-00; по предпраздничным дням – до 12-00. | AZ12: Филиал «Рефтинская ГРЭС» ПАО «Энел Россия»: 624285, РФ, Свердловская область, г. Асбест, пос. Рефтинский ИНН 6671156423 / КПП 660302001 Тел. (34365)22471, Факс: (34365) 33799 | BA12: 624285, РФ, Свердловская область, г. Асбест, пос. Рефтинский
AU13: для нужд филиала «Конаковская ГРЭС» ПАО «Энел Россия» | AV13: «Конаковская ГРЭС» | AW13: в лице своего филиала | AX13: Менеджер по ТМЦ СПР УР Константинова Наталья Ивановна Natalia.Konstantinova@enel.com +748242 3 88-07 | AY13: Понедельник – четверг: до 16-00; Пятница до 15-00; по предпраздничным дням – до 12-00. | AZ13: Филиал «Конаковская ГРЭС» ПАО «Энел Россия»: 171252, Тверская обл.,г.Конаково, ул. Промышленная, д.12 ИНН/КПП: 6671156423/691102001 Тел./факс: (48242) 3-83-59 Тел. (48242) 3-83-50, 3-83-59 | BA13: 171252, Тверская обл.,г.Конаково, ул. Промышленная, д.12
AU14: для нужд филиала «Невинномысская ГРЭС» ПАО «Энел Россия» | AV14: «Невинномысская ГРЭС» | AW14: в лице своего филиала | AX14: Менеджер ТМЦ Стрижакова Ирина Александровна Irina.Strizhakova@enel.com +7 (86554) 50403, вн. 24-03 | AY14: По согласованию с Грузополучателем | AZ14: Филиал «Невинномысская ГРЭС» ПАО «Энел Россия»: 357107, Ставропольский край, г. Невинномысск, ул. Энергетиков, 2 ИНН 6671156423 / КПП 263102001 Тел. (86554)50359, Факс: (86554) 78658 | BA14: 357107, Ставропольский край, г. Невинномысск, ул. Энергетиков, 2
AU15: для нужд филиала «Центральный офис» ПАО «Энел Россия» | AV15: «Центральный офис» | AW15: в лице своего филиала | BA15: 115093, г. Москва, ул. Павловская, дом 7, строение 1
AU16: для нужд филиалов ПАО «Энел Россия» | AV16: в лице своих филиалов | AZ16: =CONCATENATE(AZ13," ",AZ14," ",AZ12," ",AZ11) -> Филиал «Конаковская ГРЭС» ПАО «Энел Россия»: 171252, Тверская обл.,г.Конаково, ул. Промышленная, д.12 ИНН/КПП: 6671156423/691102001 Тел./факс: (48242) 3-83-59 Тел. (48242) 3-83-50, 3-83-59 Филиал «Невинномысская ГРЭС» ПАО «Энел Россия»: 357107, Ставропольский край, г. Невинномысск, ул. Энергетиков, 2 ИНН 6671156423 / КПП 263102001 Тел. (86554)50359, Факс: (86554) 78658 Филиал «Рефтинская ГРЭС» ПАО «Энел Россия»: 624285, РФ, Свердловская область, г. Асбест, пос. Рефтинский ИНН 6671156423 / КПП 660302001 Тел. (34365)22471, Факс: (34365) 33799 Филиал «Среднеуральская ГРЭС» ПАО «Энел Россия» 624070, Свердловская обл., г. Среднеуральск, ул. Ленина, 2 ИНН 6671156423 / КПП 660602001 Тел. (34368)25946, Факс: (343) 3595445 | BA16: 115093, г. Москва, ул. Павловская, дом 7, строение 1
AZ17: =CONCATENATE("Юридический адрес: 620014, Свердловская обл., г. Екатеринбург, ул. Хохрякова, дом 10 Почтовый адрес: ",VLOOKUP('1'!A18,Экспорт!$AU$11:$BA$16,7,FALSE)," ИНН/КПП: 6671156423/997450001 Р/счет: 40702810900014826390 Банк: АО ЮниКредит Банк г.Москва БИК: 044525545 Кор./счет: 30101810300000000545") -> #N/A
AT19: =R2 -> 0 | AU19: Рубли | AV19: =SUBSTITUTE(PROPER(INDEX(n_4,MID(TEXT(AT19,n0),1,1)+1)&INDEX(n0x,MID(TEXT(AT19,n0),2,1)+1,MID(TEXT(AT19,n0),3,1)+1)&IF(-MID(TEXT(AT19,n0),1,3),"миллиард"&VLOOKUP(MID(TEXT(AT19,n0),3,1)*AND(MID(TEXT(AT19,n0),2,1)-1),мил,2),"")&INDEX(n_4,MID(TEXT(AT19,n0),4,1)+1)&INDEX(n0x,MID(TEXT(AT19,n0),5,1)+1,MID(TEXT(AT19,n0),6,1)+1)&IF(-MID(TEXT(AT19,n0),4,3),"миллион"&VLOOKUP(MID(TEXT(AT19,n0),6,1)*AND(MID(TEXT(AT19,n0),5,1)-1),мил,2),"")&INDEX(n_4,MID(TEXT(AT19,n0),7,1)+1)&INDEX(n1x,MID(TEXT(AT19,n0),8,1)+1,MID(TEXT(AT19,n0),9,1)+1)&IF(-MID(TEXT(AT19,n0),7,3),VLOOKUP(MID(TEXT(AT19,n0),9,1)*AND(MID(TEXT(AT19,n0),8,1)-1),тыс,2),"")&INDEX(n_4,MID(TEXT(AT19,n0),10,1)+1)&INDEX(n0x,MID(TEXT(AT19,n0),11,1)+1,MID(TEXT(AT19,n0),12,1)+1)),"z"," ")&IF(TRUNC(TEXT(AT19,n0)),"","Ноль ")&"рубл"&VLOOKUP(MOD(MAX(MOD(MID(TEXT(AT19,n0),11,2)-11,100),9),10),{0,"ь ";1,"я ";4,"ей "},2)&RIGHT(TEXT(AT19,n0),2)&" копе"&VLOOKUP(MOD(MAX(MOD(RIGHT(TEXT(AT19,n0),2)-11,100),9),10),{0,"йка";1,"йки";4,"ек"},2) -> Ноль рублей 00 копеек
AU20: Доллары | AV20: =SUBSTITUTE(PROPER(INDEX(n_4,MID(TEXT(AT19,n0),1,1)+1)&INDEX(n0x,MID(TEXT(AT19,n0),2,1)+1,MID(TEXT(AT19,n0),3,1)+1)&IF(-MID(TEXT(AT19,n0),1,3),"миллиард"&VLOOKUP(MID(TEXT(AT19,n0),3,1)*AND(MID(TEXT(AT19,n0),2,1)-1),мил,2),"")&INDEX(n_4,MID(TEXT(AT19,n0),4,1)+1)&INDEX(n0x,MID(TEXT(AT19,n0),5,1)+1,MID(TEXT(AT19,n0),6,1)+1)&IF(-MID(TEXT(AT19,n0),4,3),"миллион"&VLOOKUP(MID(TEXT(AT19,n0),6,1)*AND(MID(TEXT(AT19,n0),5,1)-1),мил,2),"")&INDEX(n_4,MID(TEXT(AT19,n0),7,1)+1)&INDEX(n1x,MID(TEXT(AT19,n0),8,1)+1,MID(TEXT(AT19,n0),9,1)+1)&IF(-MID(TEXT(AT19,n0),7,3),VLOOKUP(MID(TEXT(AT19,n0),9,1)*AND(MID(TEXT(AT19,n0),8,1)-1),тыс,2),"")&INDEX(n_4,MID(TEXT(AT19,n0),10,1)+1)&INDEX(n0x,MID(TEXT(AT19,n0),11,1)+1,MID(TEXT(AT19,n0),12,1)+1)),"z"," ")&IF(TRUNC(TEXT(AT19,n0)),"","Ноль ")&"доллар"&VLOOKUP(MOD(MAX(MOD(MID(TEXT(AT19,n0),11,2)-11,100),9),10),{0," ";1,"а ";4,"ов "},2)&RIGHT(TEXT(AT19,n0),2)&" цент"&VLOOKUP(MOD(MAX(MOD(RIGHT(TEXT(AT19,n0),2)-11,100),9),10),{0,"";1,"а";4,"ов"},2) -> Ноль долларов 00 центов
AU21: евро | AV21: =SUBSTITUTE(PROPER(INDEX(n_4,MID(TEXT(AT19,n0),1,1)+1)&INDEX(n0x,MID(TEXT(AT19,n0),2,1)+1,MID(TEXT(AT19,n0),3,1)+1)&IF(-MID(TEXT(AT19,n0),1,3),"миллиард"&VLOOKUP(MID(TEXT(AT19,n0),3,1)*AND(MID(TEXT(AT19,n0),2,1)-1),мил,2),"")&INDEX(n_4,MID(TEXT(AT19,n0),4,1)+1)&INDEX(n0x,MID(TEXT(AT19,n0),5,1)+1,MID(TEXT(AT19,n0),6,1)+1)&IF(-MID(TEXT(AT19,n0),4,3),"миллион"&VLOOKUP(MID(TEXT(AT19,n0),6,1)*AND(MID(TEXT(AT19,n0),5,1)-1),мил,2),"")&INDEX(n_4,MID(TEXT(AT19,n0),7,1)+1)&INDEX(n1x,MID(TEXT(AT19,n0),8,1)+1,MID(TEXT(AT19,n0),9,1)+1)&IF(-MID(TEXT(AT19,n0),7,3),VLOOKUP(MID(TEXT(AT19,n0),9,1)*AND(MID(TEXT(AT19,n0),8,1)-1),тыс,2),"")&INDEX(n_4,MID(TEXT(AT19,n0),10,1)+1)&INDEX(n0x,MID(TEXT(AT19,n0),11,1)+1,MID(TEXT(AT19,n0),12,1)+1)),"z"," ")&IF(TRUNC(TEXT(AT19,n0)),"","Ноль ")&"евро"&VLOOKUP(MOD(MAX(MOD(MID(TEXT(AT19,n0),11,2)-11,100),9),10),{0," ";1," ";4," "},2)&RIGHT(TEXT(AT19,n0),2)&" цент"&VLOOKUP(MOD(MAX(MOD(RIGHT(TEXT(AT19,n0),2)-11,100),9),10),{0,"";1,"а";4,"ов"},2) -> Ноль евро 00 центов
AT23: =V2 -> 0 | AU23: Рубли | AV23: =SUBSTITUTE(PROPER(INDEX(n_4,MID(TEXT(AT23,n0),1,1)+1)&INDEX(n0x,MID(TEXT(AT23,n0),2,1)+1,MID(TEXT(AT23,n0),3,1)+1)&IF(-MID(TEXT(AT23,n0),1,3),"миллиард"&VLOOKUP(MID(TEXT(AT23,n0),3,1)*AND(MID(TEXT(AT23,n0),2,1)-1),мил,2),"")&INDEX(n_4,MID(TEXT(AT23,n0),4,1)+1)&INDEX(n0x,MID(TEXT(AT23,n0),5,1)+1,MID(TEXT(AT23,n0),6,1)+1)&IF(-MID(TEXT(AT23,n0),4,3),"миллион"&VLOOKUP(MID(TEXT(AT23,n0),6,1)*AND(MID(TEXT(AT23,n0),5,1)-1),мил,2),"")&INDEX(n_4,MID(TEXT(AT23,n0),7,1)+1)&INDEX(n1x,MID(TEXT(AT23,n0),8,1)+1,MID(TEXT(AT23,n0),9,1)+1)&IF(-MID(TEXT(AT23,n0),7,3),VLOOKUP(MID(TEXT(AT23,n0),9,1)*AND(MID(TEXT(AT23,n0),8,1)-1),тыс,2),"")&INDEX(n_4,MID(TEXT(AT23,n0),10,1)+1)&INDEX(n0x,MID(TEXT(AT23,n0),11,1)+1,MID(TEXT(AT23,n0),12,1)+1)),"z"," ")&IF(TRUNC(TEXT(AT23,n0)),"","Ноль ")&"рубл"&VLOOKUP(MOD(MAX(MOD(MID(TEXT(AT23,n0),11,2)-11,100),9),10),{0,"ь ";1,"я ";4,"ей "},2)&RIGHT(TEXT(AT23,n0),2)&" копе"&VLOOKUP(MOD(MAX(MOD(RIGHT(TEXT(AT23,n0),2)-11,100),9),10),{0,"йка";1,"йки";4,"ек"},2) -> Ноль рублей 00 копеек
AU24: Доллары | AV24: =SUBSTITUTE(PROPER(INDEX(n_4,MID(TEXT(AT23,n0),1,1)+1)&INDEX(n0x,MID(TEXT(AT23,n0),2,1)+1,MID(TEXT(AT23,n0),3,1)+1)&IF(-MID(TEXT(AT23,n0),1,3),"миллиард"&VLOOKUP(MID(TEXT(AT23,n0),3,1)*AND(MID(TEXT(AT23,n0),2,1)-1),мил,2),"")&INDEX(n_4,MID(TEXT(AT23,n0),4,1)+1)&INDEX(n0x,MID(TEXT(AT23,n0),5,1)+1,MID(TEXT(AT23,n0),6,1)+1)&IF(-MID(TEXT(AT23,n0),4,3),"миллион"&VLOOKUP(MID(TEXT(AT23,n0),6,1)*AND(MID(TEXT(AT23,n0),5,1)-1),мил,2),"")&INDEX(n_4,MID(TEXT(AT23,n0),7,1)+1)&INDEX(n1x,MID(TEXT(AT23,n0),8,1)+1,MID(TEXT(AT23,n0),9,1)+1)&IF(-MID(TEXT(AT23,n0),7,3),VLOOKUP(MID(TEXT(AT23,n0),9,1)*AND(MID(TEXT(AT23,n0),8,1)-1),тыс,2),"")&INDEX(n_4,MID(TEXT(AT23,n0),10,1)+1)&INDEX(n0x,MID(TEXT(AT23,n0),11,1)+1,MID(TEXT(AT23,n0),12,1)+1)),"z"," ")&IF(TRUNC(TEXT(AT23,n0)),"","Ноль ")&"доллар"&VLOOKUP(MOD(MAX(MOD(MID(TEXT(AT23,n0),11,2)-11,100),9),10),{0," ";1,"а ";4,"ов "},2)&RIGHT(TEXT(AT23,n0),2)&" цент"&VLOOKUP(MOD(MAX(MOD(RIGHT(TEXT(AT23,n0),2)-11,100),9),10),{0,"";1,"а";4,"ов"},2) -> Ноль долларов 00 центов
AU25: евро | AV25: =SUBSTITUTE(PROPER(INDEX(n_4,MID(TEXT(AT23,n0),1,1)+1)&INDEX(n0x,MID(TEXT(AT23,n0),2,1)+1,MID(TEXT(AT23,n0),3,1)+1)&IF(-MID(TEXT(AT23,n0),1,3),"миллиард"&VLOOKUP(MID(TEXT(AT23,n0),3,1)*AND(MID(TEXT(AT23,n0),2,1)-1),мил,2),"")&INDEX(n_4,MID(TEXT(AT23,n0),4,1)+1)&INDEX(n0x,MID(TEXT(AT23,n0),5,1)+1,MID(TEXT(AT23,n0),6,1)+1)&IF(-MID(TEXT(AT23,n0),4,3),"миллион"&VLOOKUP(MID(TEXT(AT23,n0),6,1)*AND(MID(TEXT(AT23,n0),5,1)-1),мил,2),"")&INDEX(n_4,MID(TEXT(AT23,n0),7,1)+1)&INDEX(n1x,MID(TEXT(AT23,n0),8,1)+1,MID(TEXT(AT23,n0),9,1)+1)&IF(-MID(TEXT(AT23,n0),7,3),VLOOKUP(MID(TEXT(AT23,n0),9,1)*AND(MID(TEXT(AT23,n0),8,1)-1),тыс,2),"")&INDEX(n_4,MID(TEXT(AT23,n0),10,1)+1)&INDEX(n0x,MID(TEXT(AT23,n0),11,1)+1,MID(TEXT(AT23,n0),12,1)+1)),"z"," ")&IF(TRUNC(TEXT(AT23,n0)),"","Ноль ")&"евро"&VLOOKUP(MOD(MAX(MOD(MID(TEXT(AT23,n0),11,2)-11,100),9),10),{0," ";1," ";4," "},2)&RIGHT(TEXT(AT23,n0),2)&" цент"&VLOOKUP(MOD(MAX(MOD(RIGHT(TEXT(AT23,n0),2)-11,100),9),10),{0,"";1,"а";4,"ов"},2) -> Ноль евро 00 центов
